Traceback (most recent call last):
  File "/Users/robertwexler/miniconda3/envs/comp-prob-solv/lib/python3.9/site-packages/jupyter_cache/executors/utils.py", line 58, in single_nb_execution
    executenb(
  File "/Users/robertwexler/miniconda3/envs/comp-prob-solv/lib/python3.9/site-packages/nbclient/client.py", line 1314, in execute
    return NotebookClient(nb=nb, resources=resources, km=km, **kwargs).execute()
  File "/Users/robertwexler/miniconda3/envs/comp-prob-solv/lib/python3.9/site-packages/jupyter_core/utils/__init__.py", line 165, in wrapped
    return loop.run_until_complete(inner)
  File "/Users/robertwexler/miniconda3/envs/comp-prob-solv/lib/python3.9/asyncio/base_events.py", line 647, in run_until_complete
    return future.result()
  File "/Users/robertwexler/miniconda3/envs/comp-prob-solv/lib/python3.9/site-packages/nbclient/client.py", line 709, in async_execute
    await self.async_execute_cell(
  File "/Users/robertwexler/miniconda3/envs/comp-prob-solv/lib/python3.9/site-packages/nbclient/client.py", line 1062, in async_execute_cell
    await self._check_raise_for_error(cell, cell_index, exec_reply)
  File "/Users/robertwexler/miniconda3/envs/comp-prob-solv/lib/python3.9/site-packages/nbclient/client.py", line 918, in _check_raise_for_error
    raise CellExecutionError.from_cell_and_msg(cell, exec_reply_content)
nbclient.exceptions.CellExecutionError: An error occurred while executing the following cell:
------------------
from sklearn.linear_model import RidgeCV
from sklearn.neural_network import MLPRegressor

# Train the Ridge regression model
ridge = RidgeCV()
ridge.fit(X_train, y_train)
y_pred_ridge = ridge.predict(X_test)

# Train the MLPRegressor model
mlp = MLPRegressor(
    hidden_layer_sizes=(100, 50),
    activation='relu',
    solver='adam',
    max_iter=1000,
    random_state=42
)
mlp.fit(X_train, y_train)
y_pred_mlp = mlp.predict(X_test)

# Plot the predicted vs. actual values
plt.figure(figsize=(12, 6))
plt.scatter(y_test, y_pred_ridge, label='Ridge Regression')
plt.scatter(y_test, y_pred_mlp, label='MLPRegressor')
plt.plot([y_test.min(), y_test.max()], [y_test.min(), y_test.max()], 'k--', lw=2)
plt.xlabel('Actual')
plt.ylabel('Predicted')
plt.legend()
plt.title('Predicted vs. Actual Values')
plt.aspect_equal()
plt.show()
------------------


[0;31m---------------------------------------------------------------------------[0m
[0;31mAttributeError[0m                            Traceback (most recent call last)
Cell [0;32mIn[15], line 29[0m
[1;32m     27[0m plt[38;5;241m.[39mlegend()
[1;32m     28[0m plt[38;5;241m.[39mtitle([38;5;124m'[39m[38;5;124mPredicted vs. Actual Values[39m[38;5;124m'[39m)
[0;32m---> 29[0m [43mplt[49m[38;5;241;43m.[39;49m[43maspect_equal[49m()
[1;32m     30[0m plt[38;5;241m.[39mshow()

[0;31mAttributeError[0m: module 'matplotlib.pyplot' has no attribute 'aspect_equal'

