Traceback (most recent call last):
  File "/Users/robertwexler/miniconda3/envs/comp-prob-solv/lib/python3.9/site-packages/jupyter_cache/executors/utils.py", line 58, in single_nb_execution
    executenb(
  File "/Users/robertwexler/miniconda3/envs/comp-prob-solv/lib/python3.9/site-packages/nbclient/client.py", line 1314, in execute
    return NotebookClient(nb=nb, resources=resources, km=km, **kwargs).execute()
  File "/Users/robertwexler/miniconda3/envs/comp-prob-solv/lib/python3.9/site-packages/jupyter_core/utils/__init__.py", line 165, in wrapped
    return loop.run_until_complete(inner)
  File "/Users/robertwexler/miniconda3/envs/comp-prob-solv/lib/python3.9/asyncio/base_events.py", line 647, in run_until_complete
    return future.result()
  File "/Users/robertwexler/miniconda3/envs/comp-prob-solv/lib/python3.9/site-packages/nbclient/client.py", line 709, in async_execute
    await self.async_execute_cell(
  File "/Users/robertwexler/miniconda3/envs/comp-prob-solv/lib/python3.9/site-packages/nbclient/client.py", line 1062, in async_execute_cell
    await self._check_raise_for_error(cell, cell_index, exec_reply)
  File "/Users/robertwexler/miniconda3/envs/comp-prob-solv/lib/python3.9/site-packages/nbclient/client.py", line 918, in _check_raise_for_error
    raise CellExecutionError.from_cell_and_msg(cell, exec_reply_content)
nbclient.exceptions.CellExecutionError: An error occurred while executing the following cell:
------------------
# Load the configuration of particles from the file lj.xyz
import numpy as np

def read_xyz(filename):
    with open(filename, 'r') as f:
        lines = f.readlines()
        n_atoms = int(lines[0])
        data = np.zeros((n_atoms, 3))
        for i in range(2, n_atoms + 2):
            # Skip the first column (species) and extract the x, y, z coordinates
            data[i - 2] = np.array([float(x) for x in lines[i].split()[1:4]])
    return data

# Load the configuration of particles from the file lj.xyz
filename = 'lj.xyz'
positions = read_xyz(filename)
n_atoms = len(positions)
print(f'Number of particles: {n_atoms}')
------------------


[0;31m---------------------------------------------------------------------------[0m
[0;31mFileNotFoundError[0m                         Traceback (most recent call last)
Cell [0;32mIn[1], line 16[0m
[1;32m     14[0m [38;5;66;03m# Load the configuration of particles from the file lj.xyz[39;00m
[1;32m     15[0m filename [38;5;241m=[39m [38;5;124m'[39m[38;5;124mlj.xyz[39m[38;5;124m'[39m
[0;32m---> 16[0m positions [38;5;241m=[39m [43mread_xyz[49m[43m([49m[43mfilename[49m[43m)[49m
[1;32m     17[0m n_atoms [38;5;241m=[39m [38;5;28mlen[39m(positions)
[1;32m     18[0m [38;5;28mprint[39m([38;5;124mf[39m[38;5;124m'[39m[38;5;124mNumber of particles: [39m[38;5;132;01m{[39;00mn_atoms[38;5;132;01m}[39;00m[38;5;124m'[39m)

Cell [0;32mIn[1], line 5[0m, in [0;36mread_xyz[0;34m(filename)[0m
[1;32m      4[0m [38;5;28;01mdef[39;00m [38;5;21mread_xyz[39m(filename):
[0;32m----> 5[0m     [38;5;28;01mwith[39;00m [38;5;28;43mopen[39;49m[43m([49m[43mfilename[49m[43m,[49m[43m [49m[38;5;124;43m'[39;49m[38;5;124;43mr[39;49m[38;5;124;43m'[39;49m[43m)[49m [38;5;28;01mas[39;00m f:
[1;32m      6[0m         lines [38;5;241m=[39m f[38;5;241m.[39mreadlines()
[1;32m      7[0m         n_atoms [38;5;241m=[39m [38;5;28mint[39m(lines[[38;5;241m0[39m])

File [0;32m~/miniconda3/envs/comp-prob-solv/lib/python3.9/site-packages/IPython/core/interactiveshell.py:310[0m, in [0;36m_modified_open[0;34m(file, *args, **kwargs)[0m
[1;32m    303[0m [38;5;28;01mif[39;00m file [38;5;129;01min[39;00m {[38;5;241m0[39m, [38;5;241m1[39m, [38;5;241m2[39m}:
[1;32m    304[0m     [38;5;28;01mraise[39;00m [38;5;167;01mValueError[39;00m(
[1;32m    305[0m         [38;5;124mf[39m[38;5;124m"[39m[38;5;124mIPython won[39m[38;5;124m'[39m[38;5;124mt let you open fd=[39m[38;5;132;01m{[39;00mfile[38;5;132;01m}[39;00m[38;5;124m by default [39m[38;5;124m"[39m
[1;32m    306[0m         [38;5;124m"[39m[38;5;124mas it is likely to crash IPython. If you know what you are doing, [39m[38;5;124m"[39m
[1;32m    307[0m         [38;5;124m"[39m[38;5;124myou can use builtins[39m[38;5;124m'[39m[38;5;124m open.[39m[38;5;124m"[39m
[1;32m    308[0m     )
[0;32m--> 310[0m [38;5;28;01mreturn[39;00m [43mio_open[49m[43m([49m[43mfile[49m[43m,[49m[43m [49m[38;5;241;43m*[39;49m[43margs[49m[43m,[49m[43m [49m[38;5;241;43m*[39;49m[38;5;241;43m*[39;49m[43mkwargs[49m[43m)[49m

[0;31mFileNotFoundError[0m: [Errno 2] No such file or directory: 'lj.xyz'

